<mujoco model="g1_dex1_gripper">
  <compiler angle="radian" meshdir="assets/"/>

  <option integrator="implicitfast" cone="elliptic" impratio="10" noslip_iterations="4" gravity="0 0 0"/>

  <size nkey="2"/>

  <default>
    <default class="g1">
      <joint armature="0.01" frictionloss="0.3"/>
      <site size="0.01 0.005 0.005" group="5" rgba="1 0 0 1"/>
      <general biastype="affine" gainprm="500" biasprm="0 -500 1"/>
      <default class="visual">
        <geom type="mesh" contype="0" conaffinity="0" group="2" density="0" material="metal"/>
      </default>
      <default class="collision">
        <geom type="mesh" group="3"/>
        <default class="foot">
          <geom size="0.005 0 0" type="sphere" priority="1" friction="0.6"/>
        </default>
        <default class="gripper_pad">
          <geom type="box" size="0.004 0.04 0.014"
                contype="2" conaffinity="1"
                condim="6"
                solimp="0.99 0.999 0.001" solref="0.004 1"
                friction="5 0.05 0.01"
                mass="0" priority="1"/>
        </default>
      </default>
    </default>
  </default>

  <asset>
    <material name="black" rgba="0.2 0.2 0.2 1"/>
    <material name="metal" rgba="0.7 0.7 0.7 1"/>
    <mesh name="pelvis" content_type="model/stl" file="pelvis.STL"/>
    <mesh name="pelvis_contour_link" content_type="model/stl" file="pelvis_contour_link.STL"/>
    <mesh name="left_hip_pitch_link" content_type="model/stl" file="left_hip_pitch_link.STL"/>
    <mesh name="left_hip_roll_link" content_type="model/stl" file="left_hip_roll_link.STL"/>
    <mesh name="left_hip_yaw_link" content_type="model/stl" file="left_hip_yaw_link.STL"/>
    <mesh name="left_knee_link" content_type="model/stl" file="left_knee_link.STL"/>
    <mesh name="left_ankle_pitch_link" content_type="model/stl" file="left_ankle_pitch_link.STL"/>
    <mesh name="left_ankle_roll_link" content_type="model/stl" file="left_ankle_roll_link.STL"/>
    <mesh name="right_hip_pitch_link" content_type="model/stl" file="right_hip_pitch_link.STL"/>
    <mesh name="right_hip_roll_link" content_type="model/stl" file="right_hip_roll_link.STL"/>
    <mesh name="right_hip_yaw_link" content_type="model/stl" file="right_hip_yaw_link.STL"/>
    <mesh name="right_knee_link" content_type="model/stl" file="right_knee_link.STL"/>
    <mesh name="right_ankle_pitch_link" content_type="model/stl" file="right_ankle_pitch_link.STL"/>
    <mesh name="right_ankle_roll_link" content_type="model/stl" file="right_ankle_roll_link.STL"/>
    <mesh name="waist_yaw_link" content_type="model/stl" file="waist_yaw_link_rev_1_0.STL"/>
    <mesh name="waist_roll_link" content_type="model/stl" file="waist_roll_link_rev_1_0.STL"/>
    <mesh name="torso_link" content_type="model/stl" file="torso_link_rev_1_0.STL"/>
    <mesh name="logo_link" content_type="model/stl" file="logo_link.STL"/>
    <mesh name="head_link" content_type="model/stl" file="head_link.STL"/>
    <mesh name="left_shoulder_pitch_link" content_type="model/stl" file="left_shoulder_pitch_link.STL"/>
    <mesh name="left_shoulder_roll_link" content_type="model/stl" file="left_shoulder_roll_link.STL"/>
    <mesh name="left_shoulder_yaw_link" content_type="model/stl" file="left_shoulder_yaw_link.STL"/>
    <mesh name="left_elbow_link" content_type="model/stl" file="left_elbow_link.STL"/>
    <mesh name="left_wrist_roll_link" content_type="model/stl" file="left_wrist_roll_link.STL"/>
    <mesh name="left_wrist_pitch_link" content_type="model/stl" file="left_wrist_pitch_link.STL"/>
    <mesh name="left_wrist_yaw_link" content_type="model/stl" file="left_wrist_yaw_link.STL"/>
    <mesh name="right_shoulder_pitch_link" content_type="model/stl" file="right_shoulder_pitch_link.STL"/>
    <mesh name="right_shoulder_roll_link" content_type="model/stl" file="right_shoulder_roll_link.STL"/>
    <mesh name="right_shoulder_yaw_link" content_type="model/stl" file="right_shoulder_yaw_link.STL"/>
    <mesh name="right_elbow_link" content_type="model/stl" file="right_elbow_link.STL"/>
    <mesh name="right_wrist_roll_link" content_type="model/stl" file="right_wrist_roll_link.STL"/>
    <mesh name="right_wrist_pitch_link" content_type="model/stl" file="right_wrist_pitch_link.STL"/>
    <mesh name="right_wrist_yaw_link" content_type="model/stl" file="right_wrist_yaw_link.STL"/>
    <mesh name="dex_base_link" file="base_link.STL"/>
    <mesh name="dex_Link1_1"   file="Link1_1.STL"/>
    <mesh name="dex_Link1_2"   file="Link1_2.STL"/>
    <mesh name="dex_Link1_3"   file="Link1_3.STL"/>
    <mesh name="dex_Link2_1"   file="Link2_1.STL"/>
    <mesh name="dex_Link2_2"   file="Link2_2.STL"/>
  </asset>

  <worldbody>
    <light pos="1 0 3.5" dir="0 0 -1" type="directional"/>
    <body name="pelvis" childclass="g1" pos="0 0 0.793">
      <inertial pos="0 0 -0.07605" quat="1 0 -0.000399148 0" mass="3.813" diaginertia="0.010549 0.0093089 0.0079184"/>
      <joint name="floating_base_joint" type="free" armature="0" frictionloss="0"/>
      <camera name="third_person" pos="-0.95 0 0.75" xyaxes="0 -1 0 0.5 0 0.866" fovy="75"/>
      <camera name="side_right" pos="-0.55 -0.9 0.7" xyaxes="0.7071 -0.7071 0 0.2716 0.2716 0.9233" fovy="75"/>
      <camera name="side_left" pos="-0.55 0.9 0.7" xyaxes="-0.7071 -0.7071 0 0.2716 -0.2716 0.9233" fovy="75"/>
      <geom class="visual" material="black" mesh="pelvis"/>
      <geom class="visual" mesh="pelvis_contour_link"/>
      <geom class="collision" mesh="pelvis_contour_link"/>
      <site name="imu_in_pelvis" pos="0.04525 0 -0.08339"/>
      <body name="left_hip_pitch_link" pos="0 0.064452 -0.1027">
        <inertial pos="0.002741 0.047791 -0.02606" quat="0.954862 0.293964 0.0302556 0.030122" mass="1.35" diaginertia="0.00181517 0.00153422 0.00116212"/>
        <joint name="left_hip_pitch_joint" pos="0 0 0" axis="0 1 0" range="-2.5307 2.8798" actuatorfrcrange="-88 88" armature="0.0101775" frictionloss="0"/>
        <geom class="visual" material="black" mesh="left_hip_pitch_link"/>
        <geom class="collision" mesh="left_hip_pitch_link"/>
        <body name="left_hip_roll_link" pos="0 0.052 -0.030465" quat="0.996179 0 -0.0873386 0">
          <inertial pos="0.029812 -0.001045 -0.087934" quat="0.977808 -1.97119e-05 0.205576 -0.0403793" mass="1.52" diaginertia="0.00254986 0.00241169 0.00148755"/>
          <joint name="left_hip_roll_joint" pos="0 0 0" axis="1 0 0" range="-0.5236 2.9671" actuatorfrcrange="-139 139" armature="0.0251019" frictionloss="0"/>
          <geom class="visual" mesh="left_hip_roll_link"/>
          <geom class="collision" mesh="left_hip_roll_link"/>
          <body name="left_hip_yaw_link" pos="0.025001 0 -0.12412">
            <inertial pos="-0.057709 -0.010981 -0.15078" quat="0.600598 0.15832 0.223482 0.751181" mass="1.702" diaginertia="0.00776166 0.00717575 0.00160139"/>
            <joint name="left_hip_yaw_joint" pos="0 0 0" axis="0 0 1" range="-2.7576 2.7576" actuatorfrcrange="-88 88" armature="0.0101775" frictionloss="0"/>
            <geom class="visual" mesh="left_hip_yaw_link"/>
            <geom class="collision" mesh="left_hip_yaw_link"/>
            <body name="left_knee_link" pos="-0.078273 0.0021489 -0.17734" quat="0.996179 0 0.0873386 0">
              <inertial pos="0.005457 0.003964 -0.12074" quat="0.923418 -0.0327699 0.0158246 0.382067" mass="1.932" diaginertia="0.0113804 0.0112778 0.00146458"/>
              <joint name="left_knee_joint" pos="0 0 0" axis="0 1 0" range="-0.087267 2.8798" actuatorfrcrange="-139 139" armature="0.0251019" frictionloss="0"/>
              <geom class="visual" mesh="left_knee_link"/>
              <geom class="collision" mesh="left_knee_link"/>
              <body name="left_ankle_pitch_link" pos="0 -9.4445e-05 -0.30001">
                <inertial pos="-0.007269 0 0.011137" quat="0.603053 0.369225 0.369225 0.603053" mass="0.074" diaginertia="1.89e-05 1.40805e-05 6.9195e-06"/>
                <joint name="left_ankle_pitch_joint" pos="0 0 0" axis="0 1 0" range="-0.87267 0.5236" actuatorfrcrange="-50 50" armature="0.00721945" frictionloss="0"/>
                <geom class="visual" mesh="left_ankle_pitch_link"/>
                <geom class="collision" mesh="left_ankle_pitch_link"/>
                <body name="left_ankle_roll_link" pos="0 0 -0.017558">
                  <inertial pos="0.026505 0 -0.016425" quat="-0.000481092 0.728482 -0.000618967 0.685065" mass="0.608" diaginertia="0.00167218 0.0016161 0.000217621"/>
                  <joint name="left_ankle_roll_joint" pos="0 0 0" axis="1 0 0" range="-0.2618 0.2618" actuatorfrcrange="-50 50" armature="0.00721945" frictionloss="0"/>
                  <geom class="visual" material="black" mesh="left_ankle_roll_link"/>
                  <geom class="foot" pos="-0.05 0.025 -0.03"/>
                  <geom class="foot" pos="-0.05 -0.025 -0.03"/>
                  <geom class="foot" pos="0.12 0.03 -0.03"/>
                  <geom class="foot" pos="0.12 -0.03 -0.03"/>
                  <site name="left_foot" pos="0 0 0"/>
                </body>
              </body>
            </body>
          </body>
        </body>
      </body>
      <body name="right_hip_pitch_link" pos="0 -0.064452 -0.1027">
        <inertial pos="0.002741 -0.047791 -0.02606" quat="0.954862 -0.293964 0.0302556 -0.030122" mass="1.35" diaginertia="0.00181517 0.00153422 0.00116212"/>
        <joint name="right_hip_pitch_joint" pos="0 0 0" axis="0 1 0" range="-2.5307 2.8798" actuatorfrcrange="-88 88" armature="0.0101775" frictionloss="0"/>
        <geom class="visual" material="black" mesh="right_hip_pitch_link"/>
        <geom class="collision" mesh="right_hip_pitch_link"/>
        <body name="right_hip_roll_link" pos="0 -0.052 -0.030465" quat="0.996179 0 -0.0873386 0">
          <inertial pos="0.029812 0.001045 -0.087934" quat="0.977808 1.97119e-05 0.205576 0.0403793" mass="1.52" diaginertia="0.00254986 0.00241169 0.00148755"/>
          <joint name="right_hip_roll_joint" pos="0 0 0" axis="1 0 0" range="-2.9671 0.5236" actuatorfrcrange="-139 139" armature="0.0251019" frictionloss="0"/>
          <geom class="visual" mesh="right_hip_roll_link"/>
          <geom class="collision" mesh="right_hip_roll_link"/>
          <body name="right_hip_yaw_link" pos="0.025001 0 -0.12412">
            <inertial pos="-0.057709 0.010981 -0.15078" quat="0.751181 0.223482 0.15832 0.600598" mass="1.702" diaginertia="0.00776166 0.00717575 0.00160139"/>
            <joint name="right_hip_yaw_joint" pos="0 0 0" axis="0 0 1" range="-2.7576 2.7576" actuatorfrcrange="-88 88" armature="0.0101775" frictionloss="0"/>
            <geom class="visual" mesh="right_hip_yaw_link"/>
            <geom class="collision" mesh="right_hip_yaw_link"/>
            <body name="right_knee_link" pos="-0.078273 -0.0021489 -0.17734" quat="0.996179 0 0.0873386 0">
              <inertial pos="0.005457 -0.003964 -0.12074" quat="0.923439 0.0345276 0.0116333 -0.382012" mass="1.932" diaginertia="0.011374 0.0112843 0.00146452"/>
              <joint name="right_knee_joint" pos="0 0 0" axis="0 1 0" range="-0.087267 2.8798" actuatorfrcrange="-139 139" armature="0.0251019" frictionloss="0"/>
              <geom class="visual" mesh="right_knee_link"/>
              <geom class="collision" mesh="right_knee_link"/>
              <body name="right_ankle_pitch_link" pos="0 9.4445e-05 -0.30001">
                <inertial pos="-0.007269 0 0.011137" quat="0.603053 0.369225 0.369225 0.603053" mass="0.074" diaginertia="1.89e-05 1.40805e-05 6.9195e-06"/>
                <joint name="right_ankle_pitch_joint" pos="0 0 0" axis="0 1 0" range="-0.87267 0.5236" actuatorfrcrange="-50 50" armature="0.00721945" frictionloss="0"/>
                <geom class="visual" mesh="right_ankle_pitch_link"/>
                <geom class="collision" mesh="right_ankle_pitch_link"/>
                <body name="right_ankle_roll_link" pos="0 0 -0.017558">
                  <inertial pos="0.026505 0 -0.016425" quat="0.000481092 0.728482 0.000618967 0.685065" mass="0.608" diaginertia="0.00167218 0.0016161 0.000217621"/>
                  <joint name="right_ankle_roll_joint" pos="0 0 0" axis="1 0 0" range="-0.2618 0.2618" actuatorfrcrange="-50 50" armature="0.00721945" frictionloss="0"/>
                  <geom class="visual" material="black" mesh="right_ankle_roll_link"/>
                  <geom class="foot" pos="-0.05 0.025 -0.03"/>
                  <geom class="foot" pos="-0.05 -0.025 -0.03"/>
                  <geom class="foot" pos="0.12 0.03 -0.03"/>
                  <geom class="foot" pos="0.12 -0.03 -0.03"/>
                  <site name="right_foot" pos="0 0 0"/>
                </body>
              </body>
            </body>
          </body>
        </body>
      </body>
      <body name="waist_yaw_link">
        <inertial pos="0.003494 0.000233 0.018034" quat="0.289697 0.591001 -0.337795 0.672821" mass="0.214" diaginertia="0.000163531 0.000107714 0.000102205"/>
        <joint name="waist_yaw_joint" pos="0 0 0" axis="0 0 1" range="-2.618 2.618" actuatorfrcrange="-88 88" armature="0.0101775" frictionloss="0"/>
        <geom class="visual" mesh="waist_yaw_link"/>
        <body name="waist_roll_link" pos="-0.0039635 0 0.044">
          <inertial pos="0 2.3e-05 0" quat="0.5 0.5 -0.5 0.5" mass="0.086" diaginertia="8.245e-06 7.079e-06 6.339e-06"/>
          <joint name="waist_roll_joint" pos="0 0 0" axis="1 0 0" range="-0.52 0.52" actuatorfrcrange="-50 50" armature="0.00721945" frictionloss="0"/>
          <geom class="visual" mesh="waist_roll_link"/>
          <body name="torso_link">
            <inertial pos="0.00203158 0.000339683 0.184568" quat="0.999803 -6.03319e-05 0.0198256 0.00131986" mass="7.818" diaginertia="0.121847 0.109825 0.0273735"/>
            <joint name="waist_pitch_joint" pos="0 0 0" axis="0 1 0" range="-0.52 0.52" actuatorfrcrange="-50 50" armature="0.00721945" frictionloss="0"/>
            <geom class="visual" mesh="torso_link"/>
            <geom class="collision" mesh="torso_link"/>
            <geom class="visual" pos="0.0039635 0 -0.044" quat="1 0 0 0" material="black" mesh="logo_link"/>
            <geom class="visual" pos="0.0039635 0 -0.044" material="black" mesh="head_link"/>
            <geom class="collision" pos="0.0039635 0 -0.044" mesh="head_link"/>
            <site name="imu_in_torso" pos="-0.03959 -0.00224 0.14792"/>
            <camera name="head_pov" pos="0.084 0.01753 0.41987" xyaxes="0 -1 0 0.7385 0 0.6743" fovy="110"/>
            <camera name="chest_pov" pos="0.08 0 0.22" xyaxes="0 -1 0 0.342 0 0.94" fovy="90"/>
            <body name="left_shoulder_pitch_link" pos="0.0039563 0.10022 0.24778" quat="0.990264 0.139201 1.38722e-05 -9.86868e-05">
              <inertial pos="0 0.035892 -0.011628" quat="0.654152 0.0130458 -0.326267 0.68225" mass="0.718" diaginertia="0.000465864 0.000432842 0.000406394"/>
              <joint name="left_shoulder_pitch_joint" pos="0 0 0" axis="0 1 0" range="-3.0892 2.6704" actuatorfrcrange="-25 25" armature="0.00360972" frictionloss="0"/>
              <geom class="visual" mesh="left_shoulder_pitch_link"/>
              <geom class="collision" size="0.03 0.025" pos="0 0.04 -0.01" quat="0.707107 0 0.707107 0" type="cylinder"/>
              <body name="left_shoulder_roll_link" pos="0 0.038 -0.013831" quat="0.990268 -0.139172 0 0">
                <inertial pos="-0.000227 0.00727 -0.063243" quat="0.701256 -0.0196223 -0.00710317 0.712604" mass="0.643" diaginertia="0.000691311 0.000618011 0.000388977"/>
                <joint name="left_shoulder_roll_joint" pos="0 0 0" axis="1 0 0" range="-1.5882 2.2515" actuatorfrcrange="-25 25" armature="0.00360972" frictionloss="0"/>
                <geom class="visual" mesh="left_shoulder_roll_link"/>
                <geom class="collision" size="0.03 0.015" pos="-0.004 0.006 -0.053" type="cylinder"/>
                <body name="left_shoulder_yaw_link" pos="0 0.00624 -0.1032">
                  <inertial pos="0.010773 -0.002949 -0.072009" quat="0.716879 -0.0964829 -0.0679942 0.687134" mass="0.734" diaginertia="0.00106187 0.00103217 0.000400661"/>
                  <joint name="left_shoulder_yaw_joint" pos="0 0 0" axis="0 0 1" range="-2.618 2.618" actuatorfrcrange="-25 25" armature="0.00360972" frictionloss="0"/>
                  <geom class="visual" mesh="left_shoulder_yaw_link"/>
                  <geom class="collision" mesh="left_shoulder_yaw_link"/>
                  <body name="left_elbow_link" pos="0.015783 0 -0.080518">
                    <inertial pos="0.064956 0.004454 -0.010062" quat="0.541765 0.636132 0.388821 0.388129" mass="0.6" diaginertia="0.000443035 0.000421612 0.000259353"/>
                    <joint name="left_elbow_joint" pos="0 0 0" axis="0 1 0" range="-1.0472 2.0944" actuatorfrcrange="-25 25" armature="0.00360972" frictionloss="0"/>
                    <geom class="visual" mesh="left_elbow_link"/>
                    <geom class="collision" mesh="left_elbow_link"/>
                    <body name="left_wrist_roll_link" pos="0.1 0.00188791 -0.01">
                      <inertial pos="0.0171394 0.000537591 4.8864e-07" quat="0.575338 0.411667 -0.574906 0.411094" mass="0.085445" diaginertia="5.48211e-05 4.96646e-05 3.57798e-05"/>
                      <joint name="left_wrist_roll_joint" pos="0 0 0" axis="1 0 0" range="-1.97222 1.97222" actuatorfrcrange="-25 25" armature="0.00360972" frictionloss="0"/>
                      <geom class="visual" mesh="left_wrist_roll_link"/>
                      <geom class="collision" mesh="left_wrist_roll_link"/>
                      <body name="left_wrist_pitch_link" pos="0.038 0 0">
                        <inertial pos="0.0229999 -0.00111685 -0.00111658" quat="0.249998 0.661363 0.293036 0.643608" mass="0.48405" diaginertia="0.000430353 0.000429873 0.000164648"/>
                        <joint name="left_wrist_pitch_joint" pos="0 0 0" axis="0 1 0" range="-1.61443 1.61443" actuatorfrcrange="-5 5" armature="0.00425" frictionloss="0"/>
                        <geom class="visual" mesh="left_wrist_pitch_link"/>
                        <geom class="collision" mesh="left_wrist_pitch_link"/>
                        <body name="left_wrist_yaw_link" pos="0.046 0 0">
                          <inertial pos="0.0885506 0.00212216 -0.000374562" quat="0.487149 0.493844 0.513241 0.505358" mass="0.457415" diaginertia="0.00105989 0.000895419 0.000323842"/>
                          <joint name="left_wrist_yaw_joint" pos="0 0 0" axis="0 0 1" range="-1.61443 1.61443" actuatorfrcrange="-5 5" armature="0.00425" frictionloss="0"/>
                          <geom class="visual" mesh="left_wrist_yaw_link"/>
                          <geom class="collision" mesh="left_wrist_yaw_link"/>
                          <!-- LEFT DEX1-1 GRIPPER -->
                          <body name="left_dex_base" pos="0.035 0 0" euler="0 0 -1.5708">
                            <inertial pos="0.0001178 0.036886 0.0080974" mass="0.11"
                                      fullinertia="4.9533e-05 6.8944e-05 3.4443e-05 5.9474e-08 -3.1979e-08 -1.7064e-06"/>
                            <geom class="visual" type="mesh" mesh="dex_base_link" rgba="0.2 0.2 0.2 1"/>
                            <geom class="gripper_pad" size="0.02 0.03 0.033" pos="0 0.04 0"/>
                            <geom class="gripper_pad" size="0.04 0.03 0.02"  pos="0 0.04 0"/>
                            <geom class="gripper_pad" type="cylinder" size="0.035 0.035 0.02" pos="0 0.035 0" euler="1.57 0 0"/>
                            <camera name="left_wrist_camera" pos="0 0.055 0.068" euler="1.0 0 0" fovy="100"/>
                            <site name="left_grasp" pos="0 0.13 0" size="0.005" group="5"/>
                            <body name="left_Link1_1" pos="0.04055 0.0593 0.0152">
                              <joint name="left_Joint1_1" type="slide" axis="-1 0 0" range="-0.0222 0.0245"
                                     damping="5" armature="0.2" frictionloss="0.2"
                                     solimplimit="0.95 0.99 0.001" solreflimit="0.005 1"/>
                              <inertial pos="-0.041607 0.0039411 -0.00047344" mass="0.0084398"
                                        fullinertia="1.0466e-07 3.5113e-06 3.523e-06 4.1386e-09 1.086e-09 -1.1358e-09"/>
                              <geom class="visual" type="mesh" mesh="dex_Link1_1" rgba="0.2 0.2 0.2 1"/>
                              <body name="left_Link1_2" pos="-0.013 0.013 0">
                                <inertial pos="0.0046767 0.026417 -0.014407" mass="0.028354"
                                          fullinertia="1.3423e-05 2.249e-06 1.1892e-05 3.5258e-07 5.8181e-08 6.3947e-07"/>
                                <geom class="visual" type="mesh" mesh="dex_Link1_2" rgba="0.2 0.2 0.2 1"/>
                                <body name="left_Link1_3" pos="-0.0025165 0.025043 -0.001">
                                  <inertial pos="0.0018267 0.017456 -0.0142" mass="0.004583"
                                            fullinertia="9.6165e-07 2.5948e-07 7.1226e-07 6.207e-09 -5.9626e-16 3.3171e-15"/>
                                  <geom class="visual" type="mesh" mesh="dex_Link1_3" rgba="0.2 0.2 0.2 1"/>
                                  <geom class="gripper_pad" pos="0.002 0.01 -0.014"/>
                                </body>
                              </body>
                            </body>
                            <body name="left_Link2_1" pos="-0.04055 0.0593 -0.0152">
                              <joint name="left_Joint2_1" type="slide" axis="1 0 0" range="-0.0222 0.0245"
                                     damping="5" armature="0.2" frictionloss="0.2"
                                     solimplimit="0.95 0.99 0.001" solreflimit="0.005 1"/>
                              <inertial pos="0.041607 0.0039411 0.00047344" mass="0.0084398"
                                        fullinertia="1.0466e-07 3.5113e-06 3.523e-06 -4.1386e-09 1.086e-09 1.1358e-09"/>
                              <geom class="visual" type="mesh" mesh="dex_Link2_1" rgba="0.2 0.2 0.2 1"/>
                              <body name="left_Link2_2" pos="0.013 0.013 0">
                                <inertial pos="-0.0046767 0.026417 0.014407" mass="0.028354"
                                          fullinertia="1.3423e-05 2.249e-06 1.1892e-05 -3.5258e-07 5.8181e-08 -6.3947e-07"/>
                                <geom class="visual" type="mesh" mesh="dex_Link2_2" rgba="0.2 0.2 0.2 1"/>
                                <geom class="gripper_pad" pos="0.001 0.035 0.015"/>
                              </body>
                            </body>
                          </body>
                        </body>
                      </body>
                    </body>
                  </body>
                </body>
              </body>
            </body>
            <body name="right_shoulder_pitch_link" pos="0.0039563 -0.10021 0.24778" quat="0.990264 -0.139201 1.38722e-05 9.86868e-05">
              <inertial pos="0 -0.035892 -0.011628" quat="0.68225 -0.326267 0.0130458 0.654152" mass="0.718" diaginertia="0.000465864 0.000432842 0.000406394"/>
              <joint name="right_shoulder_pitch_joint" pos="0 0 0" axis="0 1 0" range="-3.0892 2.6704" actuatorfrcrange="-88 88" armature="0.00360972" frictionloss="0"/>
              <geom class="visual" mesh="right_shoulder_pitch_link"/>
              <geom class="collision" size="0.03 0.025" pos="0 -0.04 -0.01" quat="0.707107 0 0.707107 0" type="cylinder"/>
              <body name="right_shoulder_roll_link" pos="0 -0.038 -0.013831" quat="0.990268 0.139172 0 0">
                <inertial pos="-0.000227 -0.00727 -0.063243" quat="0.712604 -0.00710317 -0.0196223 0.701256" mass="0.643" diaginertia="0.000691311 0.000618011 0.000388977"/>
                <joint name="right_shoulder_roll_joint" pos="0 0 0" axis="1 0 0" range="-2.2515 1.5882" actuatorfrcrange="-88 88" armature="0.00360972" frictionloss="0"/>
                <geom class="visual" mesh="right_shoulder_roll_link"/>
                <geom class="collision" size="0.03 0.015" pos="-0.004 -0.006 -0.053" type="cylinder"/>
                <body name="right_shoulder_yaw_link" pos="0 -0.00624 -0.1032">
                  <inertial pos="0.010773 0.002949 -0.072009" quat="0.687134 -0.0679942 -0.0964829 0.716879" mass="0.734" diaginertia="0.00106187 0.00103217 0.000400661"/>
                  <joint name="right_shoulder_yaw_joint" pos="0 0 0" axis="0 0 1" range="-2.618 2.618" actuatorfrcrange="-88 88" armature="0.00360972" frictionloss="0"/>
                  <geom class="visual" mesh="right_shoulder_yaw_link"/>
                  <geom class="collision" mesh="right_shoulder_yaw_link"/>
                  <body name="right_elbow_link" pos="0.015783 0 -0.080518">
                    <inertial pos="0.064956 -0.004454 -0.010062" quat="0.388129 0.388821 0.636132 0.541765" mass="0.6" diaginertia="0.000443035 0.000421612 0.000259353"/>
                    <joint name="right_elbow_joint" pos="0 0 0" axis="0 1 0" range="-1.0472 2.0944" actuatorfrcrange="-88 88" armature="0.00360972" frictionloss="0"/>
                    <geom class="visual" mesh="right_elbow_link"/>
                    <geom class="collision" mesh="right_elbow_link"/>
                    <body name="right_wrist_roll_link" pos="0.1 -0.00188791 -0.01">
                      <inertial pos="0.0171394 -0.000537591 4.8864e-07" quat="0.411667 0.575338 -0.411094 0.574906" mass="0.085445" diaginertia="5.48211e-05 4.96646e-05 3.57798e-05"/>
                      <joint name="right_wrist_roll_joint" pos="0 0 0" axis="1 0 0" range="-1.97222 1.97222" actuatorfrcrange="-88 88" armature="0.00360972" frictionloss="0"/>
                      <geom class="visual" mesh="right_wrist_roll_link"/>
                      <geom class="collision" mesh="right_wrist_roll_link"/>
                      <body name="right_wrist_pitch_link" pos="0.038 0 0">
                        <inertial pos="0.0229999 0.00111685 -0.00111658" quat="0.643608 0.293036 0.661363 0.249998" mass="0.48405" diaginertia="0.000430353 0.000429873 0.000164648"/>
                        <joint name="right_wrist_pitch_joint" pos="0 0 0" axis="0 1 0" range="-1.61443 1.61443" actuatorfrcrange="-88 88" armature="0.00425" frictionloss="0"/>
                        <geom class="visual" mesh="right_wrist_pitch_link"/>
                        <geom class="collision" mesh="right_wrist_pitch_link"/>
                        <body name="right_wrist_yaw_link" pos="0.046 0 0">
                          <inertial pos="0.0885506 -0.00212216 -0.000374562" quat="0.505358 0.513241 0.493844 0.487149" mass="0.457415" diaginertia="0.00105989 0.000895419 0.000323842"/>
                          <joint name="right_wrist_yaw_joint" pos="0 0 0" axis="0 0 1" range="-1.61443 1.61443" actuatorfrcrange="-88 88" armature="0.00425" frictionloss="0"/>
                          <geom class="visual" mesh="right_wrist_yaw_link"/>
                          <geom class="collision" mesh="right_wrist_yaw_link"/>
                          <!-- RIGHT DEX1-1 GRIPPER -->
                          <body name="right_dex_base" pos="0.035 0 0" euler="0 0 -1.5708">
                            <inertial pos="0.0001178 0.036886 0.0080974" mass="0.11"
                                      fullinertia="4.9533e-05 6.8944e-05 3.4443e-05 5.9474e-08 -3.1979e-08 -1.7064e-06"/>
                            <geom class="visual" type="mesh" mesh="dex_base_link" rgba="0.2 0.2 0.2 1"/>
                            <geom class="gripper_pad" size="0.02 0.03 0.033" pos="0 0.04 0"/>
                            <geom class="gripper_pad" size="0.04 0.03 0.02"  pos="0 0.04 0"/>
                            <geom class="gripper_pad" type="cylinder" size="0.035 0.035 0.02" pos="0 0.035 0" euler="1.57 0 0"/>
                            <camera name="right_wrist_camera" pos="0 0.055 0.068" euler="1.0 0 0" fovy="100"/>
                            <site name="right_grasp" pos="0 0.13 0" size="0.005" group="5"/>
                            <body name="right_Link1_1" pos="0.04055 0.0593 0.0152">
                              <joint name="right_Joint1_1" type="slide" axis="-1 0 0" range="-0.0222 0.0245"
                                     damping="5" armature="0.2" frictionloss="0.2"
                                     solimplimit="0.95 0.99 0.001" solreflimit="0.005 1"/>
                              <inertial pos="-0.041607 0.0039411 -0.00047344" mass="0.0084398"
                                        fullinertia="1.0466e-07 3.5113e-06 3.523e-06 4.1386e-09 1.086e-09 -1.1358e-09"/>
                              <geom class="visual" type="mesh" mesh="dex_Link1_1" rgba="0.2 0.2 0.2 1"/>
                              <body name="right_Link1_2" pos="-0.013 0.013 0">
                                <inertial pos="0.0046767 0.026417 -0.014407" mass="0.028354"
                                          fullinertia="1.3423e-05 2.249e-06 1.1892e-05 3.5258e-07 5.8181e-08 6.3947e-07"/>
                                <geom class="visual" type="mesh" mesh="dex_Link1_2" rgba="0.2 0.2 0.2 1"/>
                                <body name="right_Link1_3" pos="-0.0025165 0.025043 -0.001">
                                  <inertial pos="0.0018267 0.017456 -0.0142" mass="0.004583"
                                            fullinertia="9.6165e-07 2.5948e-07 7.1226e-07 6.207e-09 -5.9626e-16 3.3171e-15"/>
                                  <geom class="visual" type="mesh" mesh="dex_Link1_3" rgba="0.2 0.2 0.2 1"/>
                                  <geom class="gripper_pad" pos="0.002 0.01 -0.014"/>
                                </body>
                              </body>
                            </body>
                            <body name="right_Link2_1" pos="-0.04055 0.0593 -0.0152">
                              <joint name="right_Joint2_1" type="slide" axis="1 0 0" range="-0.0222 0.0245"
                                     damping="5" armature="0.2" frictionloss="0.2"
                                     solimplimit="0.95 0.99 0.001" solreflimit="0.005 1"/>
                              <inertial pos="0.041607 0.0039411 0.00047344" mass="0.0084398"
                                        fullinertia="1.0466e-07 3.5113e-06 3.523e-06 -4.1386e-09 1.086e-09 1.1358e-09"/>
                              <geom class="visual" type="mesh" mesh="dex_Link2_1" rgba="0.2 0.2 0.2 1"/>
                              <body name="right_Link2_2" pos="0.013 0.013 0">
                                <inertial pos="-0.0046767 0.026417 0.014407" mass="0.028354"
                                          fullinertia="1.3423e-05 2.249e-06 1.1892e-05 -3.5258e-07 5.8181e-08 -6.3947e-07"/>
                                <geom class="visual" type="mesh" mesh="dex_Link2_2" rgba="0.2 0.2 0.2 1"/>
                                <geom class="gripper_pad" pos="0.001 0.035 0.015"/>
                              </body>
                            </body>
                          </body>
                        </body>
                      </body>
                    </body>
                  </body>
                </body>
              </body>
            </body>
          </body>
        </body>
      </body>
    </body>
  </worldbody>

  <tendon>
    <fixed name="left_grip">
      <joint joint="left_Joint1_1" coef="0.5"/>
      <joint joint="left_Joint2_1" coef="0.5"/>
    </fixed>
    <fixed name="right_grip">
      <joint joint="right_Joint1_1" coef="0.5"/>
      <joint joint="right_Joint2_1" coef="0.5"/>
    </fixed>
  </tendon>

  <contact>
    <exclude body1="pelvis" body2="left_hip_roll_link"/>
    <exclude body1="pelvis" body2="right_hip_roll_link"/>
    <exclude body1="left_elbow_link" body2="left_wrist_pitch_link"/>
    <exclude body1="right_elbow_link" body2="right_wrist_pitch_link"/>
    <exclude body1="left_wrist_yaw_link"  body2="left_dex_base"/>
    <exclude body1="left_dex_base"        body2="left_Link1_1"/>
    <exclude body1="left_dex_base"        body2="left_Link2_1"/>
    <exclude body1="left_Link1_1"         body2="left_Link1_2"/>
    <exclude body1="left_Link1_2"         body2="left_Link1_3"/>
    <exclude body1="left_Link2_1"         body2="left_Link2_2"/>
    <exclude body1="right_wrist_yaw_link" body2="right_dex_base"/>
    <exclude body1="right_dex_base"       body2="right_Link1_1"/>
    <exclude body1="right_dex_base"       body2="right_Link2_1"/>
    <exclude body1="right_Link1_1"        body2="right_Link1_2"/>
    <exclude body1="right_Link1_2"        body2="right_Link1_3"/>
    <exclude body1="right_Link2_1"        body2="right_Link2_2"/>
  </contact>

  <equality>
    <joint joint1="left_Joint1_1"  joint2="left_Joint2_1"  polycoef="0 1 0 0 0"/>
    <joint joint1="right_Joint1_1" joint2="right_Joint2_1" polycoef="0 1 0 0 0"/>
  </equality>

  <actuator>
    <!-- group 0: walk actuators (mjlab values, active during walking) -->
    <general biastype="affine" name="walk_left_hip_pitch_joint" joint="left_hip_pitch_joint" group="0" gainprm="40.1792" biasprm="0 -40.1792 -2.5579" forcelimited="true" forcerange="-88 88"/>
    <general biastype="affine" name="walk_left_hip_roll_joint" joint="left_hip_roll_joint" group="0" gainprm="99.0984" biasprm="0 -99.0984 -6.3088" forcelimited="true" forcerange="-139 139"/>
    <general biastype="affine" name="walk_left_hip_yaw_joint" joint="left_hip_yaw_joint" group="0" gainprm="40.1792" biasprm="0 -40.1792 -2.5579" forcelimited="true" forcerange="-88 88"/>
    <general biastype="affine" name="walk_left_knee_joint" joint="left_knee_joint" group="0" gainprm="99.0984" biasprm="0 -99.0984 -6.3088" forcelimited="true" forcerange="-139 139"/>
    <general biastype="affine" name="walk_left_ankle_pitch_joint" joint="left_ankle_pitch_joint" group="0" gainprm="28.5012" biasprm="0 -28.5012 -1.8144" forcelimited="true" forcerange="-50 50"/>
    <general biastype="affine" name="walk_left_ankle_roll_joint" joint="left_ankle_roll_joint" group="0" gainprm="28.5012" biasprm="0 -28.5012 -1.8144" forcelimited="true" forcerange="-50 50"/>
    <general biastype="affine" name="walk_right_hip_pitch_joint" joint="right_hip_pitch_joint" group="0" gainprm="40.1792" biasprm="0 -40.1792 -2.5579" forcelimited="true" forcerange="-88 88"/>
    <general biastype="affine" name="walk_right_hip_roll_joint" joint="right_hip_roll_joint" group="0" gainprm="99.0984" biasprm="0 -99.0984 -6.3088" forcelimited="true" forcerange="-139 139"/>
    <general biastype="affine" name="walk_right_hip_yaw_joint" joint="right_hip_yaw_joint" group="0" gainprm="40.1792" biasprm="0 -40.1792 -2.5579" forcelimited="true" forcerange="-88 88"/>
    <general biastype="affine" name="walk_right_knee_joint" joint="right_knee_joint" group="0" gainprm="99.0984" biasprm="0 -99.0984 -6.3088" forcelimited="true" forcerange="-139 139"/>
    <general biastype="affine" name="walk_right_ankle_pitch_joint" joint="right_ankle_pitch_joint" group="0" gainprm="28.5012" biasprm="0 -28.5012 -1.8144" forcelimited="true" forcerange="-50 50"/>
    <general biastype="affine" name="walk_right_ankle_roll_joint" joint="right_ankle_roll_joint" group="0" gainprm="28.5012" biasprm="0 -28.5012 -1.8144" forcelimited="true" forcerange="-50 50"/>
    <general biastype="affine" name="walk_waist_yaw_joint" joint="waist_yaw_joint" group="0" gainprm="40.1792" biasprm="0 -40.1792 -2.5579" forcelimited="true" forcerange="-88 88"/>
    <general biastype="affine" name="walk_waist_roll_joint" joint="waist_roll_joint" group="0" gainprm="28.5012" biasprm="0 -28.5012 -1.8144" forcelimited="true" forcerange="-50 50"/>
    <general biastype="affine" name="walk_waist_pitch_joint" joint="waist_pitch_joint" group="0" gainprm="28.5012" biasprm="0 -28.5012 -1.8144" forcelimited="true" forcerange="-50 50"/>
    <general biastype="affine" name="walk_left_shoulder_pitch_joint" joint="left_shoulder_pitch_joint" group="0" gainprm="14.2506" biasprm="0 -14.2506 -0.9072" forcelimited="true" forcerange="-25 25"/>
    <general biastype="affine" name="walk_left_shoulder_roll_joint" joint="left_shoulder_roll_joint" group="0" gainprm="14.2506" biasprm="0 -14.2506 -0.9072" forcelimited="true" forcerange="-25 25"/>
    <general biastype="affine" name="walk_left_shoulder_yaw_joint" joint="left_shoulder_yaw_joint" group="0" gainprm="14.2506" biasprm="0 -14.2506 -0.9072" forcelimited="true" forcerange="-25 25"/>
    <general biastype="affine" name="walk_left_elbow_joint" joint="left_elbow_joint" group="0" gainprm="14.2506" biasprm="0 -14.2506 -0.9072" forcelimited="true" forcerange="-25 25"/>
    <general biastype="affine" name="walk_left_wrist_roll_joint" joint="left_wrist_roll_joint" group="0" gainprm="14.2506" biasprm="0 -14.2506 -0.9072" forcelimited="true" forcerange="-25 25"/>
    <general biastype="affine" name="walk_left_wrist_pitch_joint" joint="left_wrist_pitch_joint" group="0" gainprm="16.7783" biasprm="0 -16.7783 -1.0681" forcelimited="true" forcerange="-5 5"/>
    <general biastype="affine" name="walk_left_wrist_yaw_joint" joint="left_wrist_yaw_joint" group="0" gainprm="16.7783" biasprm="0 -16.7783 -1.0681" forcelimited="true" forcerange="-5 5"/>
    <general biastype="affine" name="walk_right_shoulder_pitch_joint" joint="right_shoulder_pitch_joint" group="0" gainprm="14.2506" biasprm="0 -14.2506 -0.9072" forcelimited="true" forcerange="-25 25"/>
    <general biastype="affine" name="walk_right_shoulder_roll_joint" joint="right_shoulder_roll_joint" group="0" gainprm="14.2506" biasprm="0 -14.2506 -0.9072" forcelimited="true" forcerange="-25 25"/>
    <general biastype="affine" name="walk_right_shoulder_yaw_joint" joint="right_shoulder_yaw_joint" group="0" gainprm="14.2506" biasprm="0 -14.2506 -0.9072" forcelimited="true" forcerange="-25 25"/>
    <general biastype="affine" name="walk_right_elbow_joint" joint="right_elbow_joint" group="0" gainprm="14.2506" biasprm="0 -14.2506 -0.9072" forcelimited="true" forcerange="-25 25"/>
    <general biastype="affine" name="walk_right_wrist_roll_joint" joint="right_wrist_roll_joint" group="0" gainprm="14.2506" biasprm="0 -14.2506 -0.9072" forcelimited="true" forcerange="-25 25"/>
    <general biastype="affine" name="walk_right_wrist_pitch_joint" joint="right_wrist_pitch_joint" group="0" gainprm="16.7783" biasprm="0 -16.7783 -1.0681" forcelimited="true" forcerange="-5 5"/>
    <general biastype="affine" name="walk_right_wrist_yaw_joint" joint="right_wrist_yaw_joint" group="0" gainprm="16.7783" biasprm="0 -16.7783 -1.0681" forcelimited="true" forcerange="-5 5"/>
    <!-- group 1: grasp actuators (high kp=500 for IK tracking, active during grasping) -->
    <position name="grasp_left_shoulder_pitch_joint" joint="left_shoulder_pitch_joint" group="1" kp="5000" dampratio="3" inheritrange="1" forcelimited="true" forcerange="-800 800"/>
    <position name="grasp_left_shoulder_roll_joint" joint="left_shoulder_roll_joint" group="1" kp="5000" dampratio="3" inheritrange="1" forcelimited="true" forcerange="-800 800"/>
    <position name="grasp_left_shoulder_yaw_joint" joint="left_shoulder_yaw_joint" group="1" kp="5000" dampratio="3" inheritrange="1" forcelimited="true" forcerange="-800 800"/>
    <position name="grasp_left_elbow_joint" joint="left_elbow_joint" group="1" kp="5000" dampratio="3" inheritrange="1" forcelimited="true" forcerange="-800 800"/>
    <position name="grasp_left_wrist_roll_joint" joint="left_wrist_roll_joint" group="1" kp="5000" dampratio="3" inheritrange="1" forcelimited="true" forcerange="-800 800"/>
    <position name="grasp_left_wrist_pitch_joint" joint="left_wrist_pitch_joint" group="1" kp="5000" dampratio="3" inheritrange="1" forcelimited="true" forcerange="-800 800"/>
    <position name="grasp_left_wrist_yaw_joint" joint="left_wrist_yaw_joint" group="1" kp="5000" dampratio="3" inheritrange="1" forcelimited="true" forcerange="-800 800"/>
    <position name="grasp_right_shoulder_pitch_joint" joint="right_shoulder_pitch_joint" group="1" kp="5000" dampratio="3" inheritrange="1" forcelimited="true" forcerange="-800 800"/>
    <position name="grasp_right_shoulder_roll_joint" joint="right_shoulder_roll_joint" group="1" kp="5000" dampratio="3" inheritrange="1" forcelimited="true" forcerange="-800 800"/>
    <position name="grasp_right_shoulder_yaw_joint" joint="right_shoulder_yaw_joint" group="1" kp="5000" dampratio="3" inheritrange="1" forcelimited="true" forcerange="-800 800"/>
    <position name="grasp_right_elbow_joint" joint="right_elbow_joint" group="1" kp="5000" dampratio="3" inheritrange="1" forcelimited="true" forcerange="-800 800"/>
    <position name="grasp_right_wrist_roll_joint" joint="right_wrist_roll_joint" group="1" kp="5000" dampratio="3" inheritrange="1" forcelimited="true" forcerange="-800 800"/>
    <position name="grasp_right_wrist_pitch_joint" joint="right_wrist_pitch_joint" group="1" kp="5000" dampratio="3" inheritrange="1" forcelimited="true" forcerange="-800 800"/>
    <position name="grasp_right_wrist_yaw_joint" joint="right_wrist_yaw_joint" group="1" kp="5000" dampratio="3" inheritrange="1" forcelimited="true" forcerange="-800 800"/>
    <position name="grasp_left_hip_pitch_joint" joint="left_hip_pitch_joint" group="1" kp="5000" dampratio="3" inheritrange="1" forcelimited="true" forcerange="-800 800"/>
    <position name="grasp_left_hip_roll_joint" joint="left_hip_roll_joint" group="1" kp="5000" dampratio="3" inheritrange="1" forcelimited="true" forcerange="-800 800"/>
    <position name="grasp_left_hip_yaw_joint" joint="left_hip_yaw_joint" group="1" kp="5000" dampratio="3" inheritrange="1" forcelimited="true" forcerange="-800 800"/>
    <position name="grasp_left_knee_joint" joint="left_knee_joint" group="1" kp="5000" dampratio="3" inheritrange="1" forcelimited="true" forcerange="-800 800"/>
    <position name="grasp_left_ankle_pitch_joint" joint="left_ankle_pitch_joint" group="1" kp="5000" dampratio="3" inheritrange="1" forcelimited="true" forcerange="-800 800"/>
    <position name="grasp_left_ankle_roll_joint" joint="left_ankle_roll_joint" group="1" kp="5000" dampratio="3" inheritrange="1" forcelimited="true" forcerange="-800 800"/>
    <position name="grasp_right_hip_pitch_joint" joint="right_hip_pitch_joint" group="1" kp="5000" dampratio="3" inheritrange="1" forcelimited="true" forcerange="-800 800"/>
    <position name="grasp_right_hip_roll_joint" joint="right_hip_roll_joint" group="1" kp="5000" dampratio="3" inheritrange="1" forcelimited="true" forcerange="-800 800"/>
    <position name="grasp_right_hip_yaw_joint" joint="right_hip_yaw_joint" group="1" kp="5000" dampratio="3" inheritrange="1" forcelimited="true" forcerange="-800 800"/>
    <position name="grasp_right_knee_joint" joint="right_knee_joint" group="1" kp="5000" dampratio="3" inheritrange="1" forcelimited="true" forcerange="-800 800"/>
    <position name="grasp_right_ankle_pitch_joint" joint="right_ankle_pitch_joint" group="1" kp="5000" dampratio="3" inheritrange="1" forcelimited="true" forcerange="-800 800"/>
    <position name="grasp_right_ankle_roll_joint" joint="right_ankle_roll_joint" group="1" kp="5000" dampratio="3" inheritrange="1" forcelimited="true" forcerange="-800 800"/>
    <position name="grasp_waist_yaw_joint" joint="waist_yaw_joint" group="1" kp="5000" dampratio="3" inheritrange="1" forcelimited="true" forcerange="-800 800"/>
    <position name="grasp_waist_roll_joint" joint="waist_roll_joint" group="1" kp="5000" dampratio="3" inheritrange="1" forcelimited="true" forcerange="-800 800"/>
    <position name="grasp_waist_pitch_joint" joint="waist_pitch_joint" group="1" kp="5000" dampratio="3" inheritrange="1" forcelimited="true" forcerange="-800 800"/>
    <!-- group 2: grippers (always active) -->
    <position name="left_grip"  tendon="left_grip"  group="2" kp="8000" kv="300" ctrlrange="-0.0222 0.0245" forcelimited="true" forcerange="-20 20"/>
    <position name="right_grip" tendon="right_grip" group="2" kp="8000" kv="300" ctrlrange="-0.0222 0.0245" forcelimited="true" forcerange="-20 20"/>
  </actuator>

  <sensor>
    <gyro site="imu_in_pelvis" name="imu_ang_vel"/>
    <velocimeter site="imu_in_pelvis" name="imu_lin_vel"/>
    <accelerometer site="imu_in_pelvis" name="imu_lin_acc"/>
    <subtreeangmom body="pelvis" name="root_angmom"/>
  </sensor>

  <!-- qpos order: freejoint(7) left_hip_p/r/y(3) left_knee(1) left_ankle_p/r(2)
       right_hip_p/r/y(3) right_knee(1) right_ankle_p/r(2) waist_y/r/p(3)
       left_shoulder_p/r/y(3) left_elbow(1) left_wrist_r/p/y(3) left_grip_j1/j2(2)
       right_shoulder_p/r/y(3) right_elbow(1) right_wrist_r/p/y(3) right_grip_j1/j2(2) = 40 -->
  <keyframe>
    <!-- qpos(40): freejoint(7) l_hip_pry(3) l_knee(1) l_ankle_pr(2) r_hip_pry(3) r_knee(1) r_ankle_pr(2) waist_yrp(3) l_shoulder_pry(3) l_elbow(1) l_wrist_rpy(3) l_grip_j1/j2(2) r_shoulder_pry(3) r_elbow(1) r_wrist_rpy(3) r_grip_j1/j2(2) -->
    <key name="stand" qpos="0 0 0.79 1 0 0 0  0 0 0 0 0 0  0 0 0 0 0 0  0 0 0  0.2 0.2 0 1.28 0 0 0  0 0  0.2 -0.2 0 1.28 0 0 0  0 0"/>
    <key name="init_state" qpos="0 0 0.76 1 0 0 0  -0.312 0 0 0.669 -0.363 0  -0.312 0 0 0.669 -0.363 0  0 0 0  0.2 0.2 0 0.6 0 0 0  0 0  0.2 -0.2 0 0.6 0 0 0  0 0"/>
  </keyframe>
</mujoco>
