<mujoco model="gripper_probe">
  <compiler angle="radian" meshdir="assets/"/>

  <asset>
    <material name="probe_metal" rgba="0.8 0.8 0.8 0.5"/>
  </asset>

  <worldbody>
    <body name="gripper_probe" pos="0 0 10" gravcomp="1">
      <freejoint name="gripper_probe_joint"/>
      <inertial pos="0 0 0" mass="0.3" diaginertia="1e-04 1e-04 1e-04"/>
      <site name="probe_grasp" pos="0 0 0" size="0.01" rgba="1 0 0 0.5"/>
      <!-- Base pad behind fingers -->
      <geom type="box" size="0.008 0.04 0.008" pos="0 0 -0.03" material="probe_metal" contype="0" conaffinity="15"/>
      <!-- Finger A pad only (open position) -->
      <body name="gripper_probe_finger_a" pos="0 0 0.01" quat="1.89468e-08 1.89469e-08 0.707108 0.707105">
        <inertial pos="0 0 0" mass="0.02" diaginertia="1e-05 1e-05 1e-05"/>
        <joint name="gripper_probe_joint_a" type="slide" axis="0 0 -1" range="0 0.04"/>
        <geom type="box" size="0.008 0.005 0.008" pos="0 -0.028 -0.005" material="probe_metal" contype="0" conaffinity="15"/>
      </body>
      <!-- Finger B pad only (open position) -->
      <body name="gripper_probe_finger_b" pos="0 0 0.01" quat="1.89468e-08 -1.89469e-08 -0.707108 0.707105">
        <inertial pos="0 0 0" mass="0.02" diaginertia="1e-05 1e-05 1e-05"/>
        <joint name="gripper_probe_joint_b" type="slide" axis="0 0 1" range="-0.04 0"/>
        <geom type="box" size="0.008 0.005 0.008" pos="0 0.028 -0.005" material="probe_metal" contype="0" conaffinity="15"/>
      </body>
    </body>
  </worldbody>

  <keyframe>
    <key name="open" qpos="0 0 10 1 0 0 0 0.04 -0.04"/>
  </keyframe>
</mujoco>
